Workbook

Sheet Start Here
B2: Step 1 · Excel practice workbook
B3: Scenario: you're the new data analyst at a council. Three teams keep separate spreadsheets about the same projects, and none of them agree. Your job: clean, match and check them.
B5: DATA SHEETS (don't edit)
B6: Register_A | C6: The PMO project register: 25 rows, project IDs PRJ-001 to PRJ-024. Contains a duplicate, a missing owner, messy text and a date error.
B7: Register_B | C7: The finance register: different codes (FIN-…), messy titles, and some projects missing or extra.
B8: Risk_Log | C8: 40 risks linked to projects. Some have no owner, some are overdue, two point to projects that don't exist.
B10: PRACTICE SHEETS
B11: Ex1_Clean | C11: Lessons 2–3: clean text and flag problems with TRIM, PROPER, IF, COUNTIF.
B12: Ex2_Crosswalk | C12: Lessons 4–5: match Register_A to Register_B with INDEX/MATCH or XLOOKUP, then compare budgets.
B13: Ex3_Risks | C13: Lessons 3, 4, 8: risk scores, ratings, overdue flags, orphan checks.
B14: Ex4_Summary | C14: Lesson 4: summary counts and totals with COUNTIFS and SUMIFS.
B15: Answers | C15: Worked formulas for every exercise. Only look after you've tried!
B17: LEGEND
B18: Yellow cells | C18: Your answer cells: type your formula in these.
B19: Green row | C19: A worked example showing the pattern. Copy it down, then work out the rest yourself.
B21: PIVOT TABLE TASKS (Lesson 6)
B22: Pivot 1 | C22: Click inside Register_A → Insert → PivotTable. Rows = Division, Values = Sum of Budget. Which division spends most?
B23: Pivot 2 | C23: Same pivot: add Status to Columns. How many Red projects does each division have? (Change Values to Count.)
B24: Pivot 3 | C24: From Risk_Log: Rows = Owner, Columns = Status, Values = Count of Risk ID. Who owns the most open risks?
B26: MINI PROJECT (Lesson 10)
B27: Deliverables | C27: 1) Finished crosswalk 2) Issue log listing every problem you found (sheet, row, problem, suggested fix) 3) A 5-line summary for your manager.

Sheet Register_A
A1: Project ID | B1: Initiative Name | C1: Owner | D1: Division | E1: Start Date | F1: End Date | G1: Budget ($) | H1: Status
A2: PRJ-001 | B2: Customer Portal Upgrade | C2: Priya Sharma | D2: Digital | E2: 45813 | F2: 46135 | G2: 455000 | H2: Green
A3: PRJ-002 | B3: Payroll System Replacement | C3: Liam O'Brien | D3: Digital | E3: 45827 | F3: 45976 | G3: 360000 | H3: Green
A4: PRJ-003 | B4: Records Digitisation | C4: James Wilson | D4: Community | E4: 45852 | F4: 46007 | G4: 190000 | H4: Green
A5: PRJ-004 | B5: Cyber Security Uplift | C5: Priya Sharma | D5: Community | E5: 45934 | F5: 46168 | G5: 440000 | H5: amber
A6: PRJ-005 | B6: Fleet Telematics Rollout | C6: Mei Chen | D6: Operations | E6: 45749 | F6: 46154 | G6: 585000 | H6: Complete
A7: PRJ-006 | B7: Data Warehouse Migration | C7: Aisha Khan | D7: Corporate | E7: 45734 | F7: 45914 | G7: 405000 | H7: Green
A8: PRJ-007 | B8: Mobile Inspections App | D8: Digital | E8: 45949 | F8: 46396 | G8: 160000 | H8: Green
A9: PRJ-008 | B9: Office Network Refresh | C9: Daniel Park | D9: Community | E9: 45932 | F9: 46368 | G9: 170000 | H9: Red
A10: PRJ-009 | B10: Grants Management System | C10: Aisha Khan | D10: Corporate | E10: 45888 | F10: 46240 | G10: 270000 | H10: Amber
A11: PRJ-009 | B11: Grants Management System | C11: Aisha Khan | D11: Corporate | E11: 45888 | F11: 46240 | G11: 270000 | H11: Amber
A12: PRJ-010 | B12: Asset Register Cleanup | C12: Aisha Khan | D12: Community | E12: 46016 | F12: 46260 | G12: 90000 | H12: Red
A13: PRJ-011 | B13: Workforce Planning Tool | C13: James Wilson | D13: Digital | E13: 46006 | F13: 46273 | G13: 425000 | H13: Complete
A14: PRJ-012 | B14: Call Centre Modernisation | C14: Daniel Park | D14: Community | E14: 45741 | F14: 45711 | G14: 135000 | H14: Green
A15: PRJ-013 | B15: Identity & Access Management | C15: Tom Nguyen | D15: Operations | E15: 45964 | F15: 46475 | G15: 395000 | H15: Red
A16: PRJ-014 | B16: Budget Reporting Automation | C16: Daniel Park | D16: Digital | E16: 45946 | F16: 46362 | G16: 550000 | H16: Green
A17: PRJ-015 | B17: website accessibility fixes | C17: James Wilson | D17: Digital | E17: 45793 | F17: 46269 | G17: 465000 | H17: Red
A18: PRJ-016 | B18: Cloud Email Migration | C18: Daniel Park | D18: Operations | E18: 45980 | F18: 46448 | G18: 565000 | H18: Complete
A19: PRJ-017 | B19: Contract Management Platform | C19: Tom Nguyen | D19: Corporate | E19: 45973 | F19: 46104 | G19: 335000 | H19: Green
A20: PRJ-018 | B20: Service Desk Replacement | C20: Aisha Khan | D20: Corporate | E20: 45871 | F20: 46102 | G20: 530000 | H20: Amber
... A26: PRJ-024 | B26: Council Meeting Livestream | C26: Priya Sharma | D26: Community | E26: 45739 | F26: 46122 | G26: 435000 | H26: Complete
B40: Click inside Register_A → Insert → PivotTable. Rows = Division, Values = Sum of Budget. Which division spends most?

Sheet Pivot_Status
A3: Sum of Budget ($) | B3: Column Labels
A4: Row Labels | B4: Amber | C4: amber | D4: Complete | E4: Green | F4: Red | G4: Grand Total
A5: Community | B5: 185000 | C5: 440000 | D5: 525000 | E5: 325000 | F5: 260000 | G5: 1735000
A6: Corporate | B6: 1070000 | E6: 740000 | G6: 1810000
A7: Digital | B7: 185000 | D7: 425000 | E7: 1525000 | F7: 465000 | G7: 2600000
A8: Operations | D8: 1710000 | F8: 525000 | G8: 2235000
A9: Grand Total | B9: 1440000 | C9: 440000 | D9: 2660000 | E9: 2590000 | F9: 1250000 | G9: 8380000

Sheet Register_B
A1: Finance Code | B1: Project Title | C1: Approved Budget ($) | D1: Forecast ($) | E1: Actual to Date ($) | F1: Match Key (you fill) =LOWER(TRIM(B2))
A2: FIN-103 | B2: RECORDS DIGITISATION | C2: 190000 | D2: 169000 | E2: 105000 | F2: =LOWER(TRIM(B2)) -> records digitisation
A3: FIN-115 | B3: contract management platform | C3: 335000 | D3: 399000 | E3: 321000 | F3: =LOWER(TRIM(B3)) -> contract management platform
A4: FIN-114 | B4: cloud email migration | C4: 535000 | D4: 626000 | E4: 457000 | F4: =LOWER(TRIM(B4)) -> cloud email migration
A5: FIN-113 | B5: Website Accessibility Fixes | C5: 465000 | D5: 429000 | E5: 372000 | F5: =LOWER(TRIM(B5)) -> website accessibility fixes
A6: FIN-107 | B6: MOBILE INSPECTIONS APP | C6: 160000 | D6: 172000 | E6: 149000 | F6: =LOWER(TRIM(B6)) -> mobile inspections app
A7: FIN-102 | B7: Payroll System Replacement | C7: 345000 | D7: 301000 | E7: 104000 | F7: =LOWER(TRIM(B7)) -> payroll system replacement
A8: FIN-118 | B8: DOCUMENT MANAGEMENT UPGRADE | C8: 185000 | D8: 197000 | E8: 148000 | F8: =LOWER(TRIM(B8)) -> document management upgrade
A9: FIN-122 | B9: Parking Sensor Trial | C9: 60000 | D9: 52000 | E9: 30000 | F9: =LOWER(TRIM(B9)) -> parking sensor trial
A10: FIN-111 | B10: IAM Program | C10: 395000 | D10: 439000 | E10: 315000 | F10: =LOWER(TRIM(B10)) -> iam program
A11: FIN-108 | B11: Grants Management System | C11: 270000 | D11: 264000 | E11: 76000 | F11: =LOWER(TRIM(B11)) -> grants management system
A12: FIN-106 | B12: Data Warehouse Migration | C12: 405000 | D12: 468000 | E12: 295000 | F12: =LOWER(TRIM(B12)) -> data warehouse migration
A13: FIN-110 | B13: Call Centre Modernisation | C13: 135000 | D13: 129000 | E13: 39000 | F13: =LOWER(TRIM(B13)) -> call centre modernisation
... A23: FIN-117 | B23: procurement portal | C23: 530000 | D23: 551000 | E23: 304000 | F23: =LOWER(TRIM(B23)) -> procurement portal

Sheet Pivot_risk
A3: Count of Risk ID | B3: Column Labels
A4: Row Labels | B4: Closed | C4: Monitoring | D4: Open | E4: Grand Total
A5: Aisha Khan | D5: 5 | E5: 5
A6: Daniel Park | B6: 1 | C6: 1 | D6: 1 | E6: 3
A7: James Wilson | D7: 4 | E7: 4
A8: Liam O'Brien | C8: 3 | D8: 2 | E8: 5
A9: Mei Chen | D9: 1 | E9: 1
A10: Priya Sharma | B10: 2 | D10: 4 | E10: 6
A11: Sarah Jones | B11: 1 | C11: 1 | D11: 2 | E11: 4
A12: Tom Nguyen | C12: 2 | D12: 1 | E12: 3
A13: (blank) | B13: 2 | C13: 1 | D13: 6 | E13: 9
A14: Grand Total | B14: 6 | C14: 8 | D14: 26 | E14: 40

Sheet Risk_Log
A1: Risk ID | B1: Project ID | C1: Description | D1: Owner | E1: Likelihood (1-5) | F1: Impact (1-5) | G1: Next Review | H1: Status
A2: R-001 | B2: PRJ-010 | C2: Scope creep | D2: Daniel Park | E2: 5 | F2: 5 | G2: 46357 | H2: Monitoring
A3: R-002 | B3: PRJ-020 | C3: Data migration errors | D3: James Wilson | E3: 1 | F3: 4 | G3: 46379 | H3: Open
A4: R-003 | B4: PRJ-015 | C4: Budget overrun | D4: Sarah Jones | E4: 3 | F4: 1 | G4: 46380 | H4: Monitoring
A5: R-004 | B5: PRJ-014 | C5: Security vulnerability found | D5: James Wilson | E5: 2 | F5: 2 | G5: 46204 | H5: Open
A6: R-005 | B6: PRJ-018 | C6: Stakeholder resistance | D6: Mei Chen | E6: 5 | F6: 5 | G6: 46287 | H6: Open
A7: R-006 | B7: PRJ-031 | C7: Licensing cost increase | E7: 2 | F7: 1 | G7: 46199 | H7: Open
A8: R-007 | B8: PRJ-016 | C8: Budget overrun | D8: Sarah Jones | E8: 2 | F8: 2 | G8: 46182 | H8: Open
A9: R-008 | B9: PRJ-009 | C9: Licensing cost increase | D9: Liam O'Brien | E9: 5 | F9: 3 | G9: 46252 | H9: Monitoring
A10: R-009 | B10: PRJ-005 | C10: Vendor delivery delay | D10: Tom Nguyen | E10: 4 | F10: 5 | G10: 46373 | H10: Monitoring
A11: R-010 | B11: PRJ-016 | C11: Budget overrun | E11: 2 | F11: 5 | G11: 46296 | H11: Monitoring
A12: R-011 | B12: PRJ-024 | C12: Budget overrun | D12: Priya Sharma | E12: 2 | F12: 2 | G12: 46219 | H12: Closed
A13: R-012 | B13: PRJ-023 | C13: Key staff unavailable | E13: 1 | F13: 3 | G13: 46343 | H13: Closed
A14: R-013 | B14: PRJ-017 | C14: Stakeholder resistance | D14: James Wilson | E14: 5 | F14: 1 | G14: 46210 | H14: Open
A15: R-014 | B15: PRJ-002 | C15: Key staff unavailable | E15: 4 | F15: 5 | G15: 46198 | H15: Open
A16: R-015 | B16: PRJ-014 | C16: Data migration errors | E16: 5 | F16: 5 | G16: 46226 | H16: Open
A17: R-016 | B17: PRJ-014 | C17: Licensing cost increase | E17: 4 | F17: 5 | G17: 46226 | H17: Closed
A18: R-017 | B18: PRJ-009 | C18: Licensing cost increase | D18: Liam O'Brien | E18: 4 | F18: 2 | G18: 46269 | H18: Monitoring
A19: R-018 | B19: PRJ-014 | C19: Data migration errors | D19: James Wilson | E19: 2 | F19: 4 | G19: 46180 | H19: Open
A20: R-019 | B20: PRJ-004 | C20: Budget overrun | D20: Tom Nguyen | E20: 2 | F20: 3 | G20: 46218 | H20: Open
A21: R-020 | B21: PRJ-023 | C21: Key staff unavailable | D21: Sarah Jones | E21: 4 | F21: 2 | G21: 46353 | H21: Open
A22: R-021 | B22: PRJ-006 | C22: Security vulnerability found | E22: 4 | F22: 3 | G22: 46272 | H22: Open
A23: R-022 | B23: PRJ-010 | C23: Key staff unavailable | D23: Tom Nguyen | E23: 1 | F23: 3 | G23: 46310 | H23: Monitoring
A24: R-023 | B24: PRJ-045 | C24: Vendor delivery delay | D24: Sarah Jones | E24: 3 | F24: 5 | G24: 46305 | H24: Closed
A25: R-024 | B25: PRJ-003 | C25: Key staff unavailable | D25: Liam O'Brien | E25: 1 | F25: 1 | G25: 46243 | H25: Open
A26: R-025 | B26: PRJ-024 | C26: Budget overrun | D26: Aisha Khan | E26: 2 | F26: 4 | G26: 46378 | H26: Open
A27: R-026 | B27: PRJ-012 | C27: Budget overrun | E27: 5 | F27: 5 | G27: 46288 | H27: Open
A28: R-027 | B28: PRJ-003 | C28: Integration failure | D28: Priya Sharma | E28: 2 | F28: 4 | G28: 46182 | H28: Open
A29: R-028 | B29: PRJ-020 | C29: Key staff unavailable | D29: Aisha Khan | E29: 1 | F29: 5 | G29: 46364 | H29: Open
A30: R-029 | B30: PRJ-009 | C30: Key staff unavailable | D30: Daniel Park | E30: 1 | F30: 3 | G30: 46309 | H30: Open
A31: R-030 | B31: PRJ-019 | C31: Budget overrun | D31: Priya Sharma | E31: 5 | F31: 2 | G31: 46179 | H31: Open
A32: R-031 | B32: PRJ-002 | C32: Budget overrun | D32: Liam O'Brien | E32: 3 | F32: 3 | G32: 46320 | H32: Open
A33: R-032 | B33: PRJ-009 | C33: Stakeholder resistance | E33: 2 | F33: 3 | G33: 46260 | H33: Open
A34: R-033 | B34: PRJ-009 | C34: Vendor delivery delay | D34: Priya Sharma | E34: 1 | F34: 5 | G34: 46302 | H34: Closed
A35: R-034 | B35: PRJ-015 | C35: Scope creep | D35: Daniel Park | E35: 1 | F35: 4 | G35: 46342 | H35: Closed
A36: R-035 | B36: PRJ-012 | C36: Licensing cost increase | D36: Aisha Khan | E36: 2 | F36: 2 | G36: 46241 | H36: Open
A37: R-036 | B37: PRJ-012 | C37: Data migration errors | D37: Priya Sharma | E37: 2 | F37: 1 | G37: 46194 | H37: Open
A38: R-037 | B38: PRJ-013 | C38: Budget overrun | D38: Priya Sharma | E38: 1 | F38: 4 | G38: 46373 | H38: Open
A39: R-038 | B39: PRJ-019 | C39: Scope creep | D39: Aisha Khan | E39: 1 | F39: 4 | G39: 46209 | H39: Open
A40: R-039 | B40: PRJ-014 | C40: Vendor delivery delay | D40: Aisha Khan | E40: 3 | F40: 3 | G40: 46306 | H40: Open
...

Sheet Ex1_Clean
A1: Project ID | B1: Initiative Name (raw) | C1: Owner (raw) | D1: Status (raw) | E1: Clean Name =TRIM(PROPER()) | F1: Clean Status | G1: Owner Missing? | H1: Duplicate ID? | I1: Dates OK?
A2: =Register_A!A2 -> PRJ-001 | B2: =Register_A!B2 -> Customer Portal Upgrade | C2: =Register_A!C2 -> Priya Sharma | D2: =Register_A!H2 -> Green | E2: =TRIM(PROPER(B2)) -> Customer Portal Upgrade | F2: =TRIM(PROPER(D2)) -> Green | G2: {=IF(C2="",fuck,"OK")} -> OK | H2: =IF(COUNTIF($A$2:$A$26,A2)>1,"DUPLICATE","OK") -> OK | I2: =IF(Register_A!F2<Register_A!E2,"END BEFORE START","OK") -> OK
A3: =Register_A!A3 -> PRJ-002 | B3: =Register_A!B3 -> Payroll System Replacement | C3: =Register_A!C3 -> Liam O'Brien | D3: =Register_A!H3 -> Green | E3: =TRIM(PROPER(B3)) -> Payroll System Replacement | F3: =TRIM(PROPER(D3)) -> Green | G3: =IF(C3="","MISSING","OK") -> OK | H3: =IF(COUNTIF($A$2:$A$26,A3)>1,"DUPLICATE","OK") -> OK | I3: =IF(Register_A!F3<Register_A!E3,"END BEFORE START","OK") -> OK
A4: =Register_A!A4 -> PRJ-003 | B4: =Register_A!B4 -> Records Digitisation | C4: =Register_A!C4 -> James Wilson | D4: =Register_A!H4 -> Green | E4: =TRIM(PROPER(B4)) -> Records Digitisation | F4: =TRIM(PROPER(D4)) -> Green | G4: =IF(C4="","MISSING","OK") -> OK | H4: =IF(COUNTIF($A$2:$A$26,A4)>1,"DUPLICATE","OK") -> OK | I4: =IF(Register_A!F4<Register_A!E4,"END BEFORE START","OK") -> OK
A5: =Register_A!A5 -> PRJ-004 | B5: =Register_A!B5 -> Cyber Security Uplift | C5: =Register_A!C5 -> Priya Sharma | D5: =Register_A!H5 -> amber | E5: =TRIM(PROPER(B5)) -> Cyber Security Uplift | F5: =TRIM(PROPER(D5)) -> Amber | G5: =IF(C5="","MISSING","OK") -> OK | H5: =IF(COUNTIF($A$2:$A$26,A5)>1,"DUPLICATE","OK") -> OK | I5: =IF(Register_A!F5<Register_A!E5,"END BEFORE START","OK") -> OK
A6: =Register_A!A6 -> PRJ-005 | B6: =Register_A!B6 -> Fleet Telematics Rollout | C6: =Register_A!C6 -> Mei Chen | D6: =Register_A!H6 -> Complete | E6: =TRIM(PROPER(B6)) -> Fleet Telematics Rollout | F6: =TRIM(PROPER(D6)) -> Complete | G6: =IF(C6="","MISSING","OK") -> OK | H6: =IF(COUNTIF($A$2:$A$26,A6)>1,"DUPLICATE","OK") -> OK | I6: =IF(Register_A!F6<Register_A!E6,"END BEFORE START","OK") -> OK
A7: =Register_A!A7 -> PRJ-006 | B7: =Register_A!B7 -> Data Warehouse Migration | C7: =Register_A!C7 -> Aisha Khan | D7: =Register_A!H7 -> Green | E7: =TRIM(PROPER(B7)) -> Data Warehouse Migration | F7: =TRIM(PROPER(D7)) -> Green | G7: =IF(C7="","MISSING","OK") -> OK | H7: =IF(COUNTIF($A$2:$A$26,A7)>1,"DUPLICATE","OK") -> OK | I7: =IF(Register_A!F7<Register_A!E7,"END BEFORE START","OK") -> OK
A8: =Register_A!A8 -> PRJ-007 | B8: =Register_A!B8 -> Mobile Inspections App | C8: =Register_A!C8 -> 0 | D8: =Register_A!H8 -> Green | E8: =TRIM(PROPER(B8)) -> Mobile Inspections App | F8: =TRIM(PROPER(D8)) -> Green | G8: =IF(C8="","MISSING","OK") -> OK | H8: =IF(COUNTIF($A$2:$A$26,A8)>1,"DUPLICATE","OK") -> OK | I8: =IF(Register_A!F8<Register_A!E8,"END BEFORE START","OK") -> OK
A9: =Register_A!A9 -> PRJ-008 | B9: =Register_A!B9 -> Office Network Refresh | C9: =Register_A!C9 -> Daniel Park | D9: =Register_A!H9 -> Red | E9: =TRIM(PROPER(B9)) -> Office Network Refresh | F9: =TRIM(PROPER(D9)) -> Red | G9: =IF(C9="","MISSING","OK") -> OK | H9: =IF(COUNTIF($A$2:$A$26,A9)>1,"DUPLICATE","OK") -> OK | I9: =IF(Register_A!F9<Register_A!E9,"END BEFORE START","OK") -> OK
A10: =Register_A!A10 -> PRJ-009 | B10: =Register_A!B10 -> Grants Management System | C10: =Register_A!C10 -> Aisha Khan | D10: =Register_A!H10 -> Amber | E10: =TRIM(PROPER(B10)) -> Grants Management System | F10: =TRIM(PROPER(D10)) -> Amber | G10: =IF(C10="","MISSING","OK") -> OK | H10: =IF(COUNTIF($A$2:$A$26,A10)>1,"DUPLICATE","OK") -> DUPLICATE | I10: =IF(Register_A!F10<Register_A!E10,"END BEFORE START","OK") -> OK
A11: =Register_A!A11 -> PRJ-009 | B11: =Register_A!B11 -> Grants Management System | C11: =Register_A!C11 -> Aisha Khan | D11: =Register_A!H11 -> Amber | E11: =TRIM(PROPER(B11)) -> Grants Management System | F11: =TRIM(PROPER(D11)) -> Amber | G11: =IF(C11="","MISSING","OK") -> OK | H11: =IF(COUNTIF($A$2:$A$26,A11)>1,"DUPLICATE","OK") -> DUPLICATE | I11: =IF(Register_A!F11<Register_A!E11,"END BEFORE START","OK") -> OK
A12: =Register_A!A12 -> PRJ-010 | B12: =Register_A!B12 -> Asset Register Cleanup | C12: =Register_A!C12 -> Aisha Khan | D12: =Register_A!H12 -> Red | E12: =TRIM(PROPER(B12)) -> Asset Register Cleanup | F12: =TRIM(PROPER(D12)) -> Red | G12: =IF(C12="","MISSING","OK") -> OK | H12: =IF(COUNTIF($A$2:$A$26,A12)>1,"DUPLICATE","OK") -> OK | I12: =IF(Register_A!F12<Register_A!E12,"END BEFORE START","OK") -> OK
A13: =Register_A!A13 -> PRJ-011 | B13: =Register_A!B13 -> Workforce Planning Tool | C13: =Register_A!C13 -> James Wilson | D13: =Register_A!H13 -> Complete | E13: =TRIM(PROPER(B13)) -> Workforce Planning Tool | F13: =TRIM(PROPER(D13)) -> Complete | G13: =IF(C13="","MISSING","OK") -> OK | H13: =IF(COUNTIF($A$2:$A$26,A13)>1,"DUPLICATE","OK") -> OK | I13: =IF(Register_A!F13<Register_A!E13,"END BEFORE START","OK") -> OK
A14: =Register_A!A14 -> PRJ-012 | B14: =Register_A!B14 -> Call Centre Modernisation | C14: =Register_A!C14 -> Daniel Park | D14: =Register_A!H14 -> Green | E14: =TRIM(PROPER(B14)) -> Call Centre Modernisation | F14: =TRIM(PROPER(D14)) -> Green | G14: =IF(C14="","MISSING","OK") -> OK | H14: =IF(COUNTIF($A$2:$A$26,A14)>1,"DUPLICATE","OK") -> OK | I14: =IF(Register_A!F14<Register_A!E14,"END BEFORE START","OK") -> END BEFORE START
... A20: =Register_A!A20 -> PRJ-018 | B20: =Register_A!B20 -> Service Desk Replacement | C20: =Register_A!C20 -> Aisha Khan | D20: =Register_A!H20 -> Amber | E20: =TRIM(PROPER(B20)) -> Service Desk Replacement | F20: =TRIM(PROPER(D20)) -> Amber | G20: =IF(C20="","MISSING","OK") -> OK | H20: =IF(COUNTIF($A$2:$A$26,A20)>1,"DUPLICATE","OK") -> OK | I20: =IF(Register_A!F20<Register_A!E20,"END BEFORE START","OK") -> OK
A21: =Register_A!A21 -> PRJ-019 | B21: =Register_A!B21 -> GIS Mapping Upgrade | C21: =Register_A!C21 -> Mei Chen | D21: =Register_A!H21 -> Complete | E21: GIS Mapping Upgrade | F21: =TRIM(PROPER(D21)) -> Complete | G21: =IF(C21="","MISSING","OK") -> OK | H21: =IF(COUNTIF($A$2:$A$26,A21)>1,"DUPLICATE","OK") -> OK | I21: =IF(Register_A!F21<Register_A!E21,"END BEFORE START","OK") -> OK
A22: =Register_A!A22 -> PRJ-020 | B22: =Register_A!B22 -> Procurement Portal | C22: =Register_A!C22 -> Sarah Jones | D22: =Register_A!H22 -> Complete | E22: =TRIM(PROPER(B22)) -> Procurement Portal | F22: =TRIM(PROPER(D22)) -> Complete | G22: =IF(C22="","MISSING","OK") -> OK | H22: =IF(COUNTIF($A$2:$A$26,A22)>1,"DUPLICATE","OK") -> OK | I22: =IF(Register_A!F22<Register_A!E22,"END BEFORE START","OK") -> OK
A23: =Register_A!A23 -> PRJ-021 | B23: =Register_A!B23 -> Document Management Upgrade | C23: =Register_A!C23 -> Mei Chen | D23: =Register_A!H23 -> Amber | E23: =TRIM(PROPER(B23)) -> Document Management Upgrade | F23: =TRIM(PROPER(D23)) -> Amber | G23: =IF(C23="","MISSING","OK") -> OK | H23: =IF(COUNTIF($A$2:$A$26,A23)>1,"DUPLICATE","OK") -> OK | I23: =IF(Register_A!F23<Register_A!E23,"END BEFORE START","OK") -> OK
A24: =Register_A!A24 -> PRJ-022 | B24: =Register_A!B24 -> Data Governance Framework | C24: =Register_A!C24 -> Priya Sharma | D24: =Register_A!H24 -> Amber | E24: =TRIM(PROPER(B24)) -> Data Governance Framework | F24: =TRIM(PROPER(D24)) -> Amber | G24: =IF(C24="","MISSING","OK") -> OK | H24: =IF(COUNTIF($A$2:$A$26,A24)>1,"DUPLICATE","OK") -> OK | I24: =IF(Register_A!F24<Register_A!E24,"END BEFORE START","OK") -> OK
A25: =Register_A!A25 -> PRJ-023 | B25: =Register_A!B25 -> Electric Vehicle Charging | C25: =Register_A!C25 -> Sarah Jones | D25: =Register_A!H25 -> Red | E25: =TRIM(PROPER(B25)) -> Electric Vehicle Charging | F25: =TRIM(PROPER(D25)) -> Red | G25: =IF(C25="","MISSING","OK") -> OK | H25: =IF(COUNTIF($A$2:$A$26,A25)>1,"DUPLICATE","OK") -> OK | I25: =IF(Register_A!F25<Register_A!E25,"END BEFORE START","OK") -> OK
A26: =Register_A!A26 -> PRJ-024 | B26: =Register_A!B26 -> Council Meeting Livestream | C26: =Register_A!C26 -> Priya Sharma | D26: =Register_A!H26 -> Complete | E26: =TRIM(PROPER(B26)) -> Council Meeting Livestream | F26: =TRIM(PROPER(D26)) -> Complete | G26: =IF(C26="","MISSING","OK") -> OK | H26: =IF(COUNTIF($A$2:$A$26,A26)>1,"DUPLICATE","OK") -> OK | I26: =IF(Register_A!F26<Register_A!E26,"END BEFORE START","OK") -> OK

Sheet Ex2_Crosswalk
A1: Project ID | B1: Initiative Name | C1: Budget A ($) | D1: Match Key (clean name) | E1: Finance Code | F1: Budget B ($) | G1: Difference ($) | H1: Result
A2: =Register_A!A2 -> PRJ-001 | B2: =Register_A!B2 -> Customer Portal Upgrade | C2: =Register_A!G2 -> 455000 | D2: =LOWER(TRIM(B2)) -> customer portal upgrade | E2: =IFERROR(INDEX(Register_B!$A$2:$A$23,MATCH(D2,Register_B!$F$2:$F$23,0)),"NOT FOUND") -> FIN-101 | F2: =IF(E2="NOT FOUND","",INDEX(Register_B!$C$2:$C$23,MATCH(E2,Register_B!$A$2:$A$23,0))) -> 455000 | G2: =IF(F2="","",F2-C2) -> 0 | H2: =IF(E2="NOT FOUND","Missing in finance",IF(G2<>0,"Budget mismatch","Match")) -> Match
A3: =Register_A!A3 -> PRJ-002 | B3: =Register_A!B3 -> Payroll System Replacement | C3: =Register_A!G3 -> 360000 | D3: =LOWER(TRIM(B3)) -> payroll system replacement | E3: =IFERROR(INDEX(Register_B!$A$2:$A$23,MATCH(D3,Register_B!$F$2:$F$23,0)),"NOT FOUND") -> FIN-102 | F3: =IF(E3="NOT FOUND","",INDEX(Register_B!$C$2:$C$23,MATCH(E3,Register_B!$A$2:$A$23,0))) -> 345000 | G3: =IF(F3="","",F3-C3) -> -15000 | H3: =IF(E3="NOT FOUND","Missing in finance",IF(G3<>0,"Budget mismatch","Match")) -> Budget mismatch
A4: =Register_A!A4 -> PRJ-003 | B4: =Register_A!B4 -> Records Digitisation | C4: =Register_A!G4 -> 190000 | D4: =LOWER(TRIM(B4)) -> records digitisation | E4: =IFERROR(INDEX(Register_B!$A$2:$A$23,MATCH(D4,Register_B!$F$2:$F$23,0)),"NOT FOUND") -> FIN-103 | F4: =IF(E4="NOT FOUND","",INDEX(Register_B!$C$2:$C$23,MATCH(E4,Register_B!$A$2:$A$23,0))) -> 190000 | G4: =IF(F4="","",F4-C4) -> 0 | H4: =IF(E4="NOT FOUND","Missing in finance",IF(G4<>0,"Budget mismatch","Match")) -> Match
A5: =Register_A!A5 -> PRJ-004 | B5: =Register_A!B5 -> Cyber Security Uplift | C5: =Register_A!G5 -> 440000 | D5: =LOWER(TRIM(B5)) -> cyber security uplift | E5: =IFERROR(INDEX(Register_B!$A$2:$A$23,MATCH(D5,Register_B!$F$2:$F$23,0)),"NOT FOUND") -> FIN-104 | F5: =IF(E5="NOT FOUND","",INDEX(Register_B!$C$2:$C$23,MATCH(E5,Register_B!$A$2:$A$23,0))) -> 440000 | G5: =IF(F5="","",F5-C5) -> 0 | H5: =IF(E5="NOT FOUND","Missing in finance",IF(G5<>0,"Budget mismatch","Match")) -> Match
A6: =Register_A!A6 -> PRJ-005 | B6: =Register_A!B6 -> Fleet Telematics Rollout | C6: =Register_A!G6 -> 585000 | D6: =LOWER(TRIM(B6)) -> fleet telematics rollout | E6: =IFERROR(INDEX(Register_B!$A$2:$A$23,MATCH(D6,Register_B!$F$2:$F$23,0)),"NOT FOUND") -> FIN-105 | F6: =IF(E6="NOT FOUND","",INDEX(Register_B!$C$2:$C$23,MATCH(E6,Register_B!$A$2:$A$23,0))) -> 585000 | G6: =IF(F6="","",F6-C6) -> 0 | H6: =IF(E6="NOT FOUND","Missing in finance",IF(G6<>0,"Budget mismatch","Match")) -> Match
A7: =Register_A!A7 -> PRJ-006 | B7: =Register_A!B7 -> Data Warehouse Migration | C7: =Register_A!G7 -> 405000 | D7: =LOWER(TRIM(B7)) -> data warehouse migration | E7: =IFERROR(INDEX(Register_B!$A$2:$A$23,MATCH(D7,Register_B!$F$2:$F$23,0)),"NOT FOUND") -> FIN-106 | F7: =IF(E7="NOT FOUND","",INDEX(Register_B!$C$2:$C$23,MATCH(E7,Register_B!$A$2:$A$23,0))) -> 405000 | G7: =IF(F7="","",F7-C7) -> 0 | H7: =IF(E7="NOT FOUND","Missing in finance",IF(G7<>0,"Budget mismatch","Match")) -> Match
A8: =Register_A!A8 -> PRJ-007 | B8: =Register_A!B8 -> Mobile Inspections App | C8: =Register_A!G8 -> 160000 | D8: =LOWER(TRIM(B8)) -> mobile inspections app | E8: =IFERROR(INDEX(Register_B!$A$2:$A$23,MATCH(D8,Register_B!$F$2:$F$23,0)),"NOT FOUND") -> FIN-107 | F8: =IF(E8="NOT FOUND","",INDEX(Register_B!$C$2:$C$23,MATCH(E8,Register_B!$A$2:$A$23,0))) -> 160000 | G8: =IF(F8="","",F8-C8) -> 0 | H8: =IF(E8="NOT FOUND","Missing in finance",IF(G8<>0,"Budget mismatch","Match")) -> Match
A9: =Register_A!A9 -> PRJ-008 | B9: =Register_A!B9 -> Office Network Refresh | C9: =Register_A!G9 -> 170000 | D9: =LOWER(TRIM(B9)) -> office network refresh | E9: =IFERROR(INDEX(Register_B!$A$2:$A$23,MATCH(D9,Register_B!$F$2:$F$23,0)),"NOT FOUND") -> NOT FOUND | F9: =IF(E9="NOT FOUND","",INDEX(Register_B!$C$2:$C$23,MATCH(E9,Register_B!$A$2:$A$23,0))) | G9: =IF(F9="","",F9-C9) | H9: =IF(E9="NOT FOUND","Missing in finance",IF(G9<>0,"Budget mismatch","Match")) -> Missing in finance
A10: =Register_A!A10 -> PRJ-009 | B10: =Register_A!B10 -> Grants Management System | C10: =Register_A!G10 -> 270000 | D10: =LOWER(TRIM(B10)) -> grants management system | E10: =IFERROR(INDEX(Register_B!$A$2:$A$23,MATCH(D10,Register_B!$F$2:$F$23,0)),"NOT FOUND") -> FIN-108 | F10: =IF(E10="NOT FOUND","",INDEX(Register_B!$C$2:$C$23,MATCH(E10,Register_B!$A$2:$A$23,0))) -> 270000 | G10: =IF(F10="","",F10-C10) -> 0 | H10: =IF(E10="NOT FOUND","Missing in finance",IF(G10<>0,"Budget mismatch","Match")) -> Match
A11: =Register_A!A11 -> PRJ-009 | B11: =Register_A!B11 -> Grants Management System | C11: =Register_A!G11 -> 270000 | D11: =LOWER(TRIM(B11)) -> grants management system | E11: =IFERROR(INDEX(Register_B!$A$2:$A$23,MATCH(D11,Register_B!$F$2:$F$23,0)),"NOT FOUND") -> FIN-108 | F11: =IF(E11="NOT FOUND","",INDEX(Register_B!$C$2:$C$23,MATCH(E11,Register_B!$A$2:$A$23,0))) -> 270000 | G11: =IF(F11="","",F11-C11) -> 0 | H11: =IF(E11="NOT FOUND","Missing in finance",IF(G11<>0,"Budget mismatch","Match")) -> Match
A12: =Register_A!A12 -> PRJ-010 | B12: =Register_A!B12 -> Asset Register Cleanup | C12: =Register_A!G12 -> 90000 | D12: =LOWER(TRIM(B12)) -> asset register cleanup | E12: =IFERROR(INDEX(Register_B!$A$2:$A$23,MATCH(D12,Register_B!$F$2:$F$23,0)),"NOT FOUND") -> FIN-109 | F12: =IF(E12="NOT FOUND","",INDEX(Register_B!$C$2:$C$23,MATCH(E12,Register_B!$A$2:$A$23,0))) -> 90000 | G12: =IF(F12="","",F12-C12) -> 0 | H12: =IF(E12="NOT FOUND","Missing in finance",IF(G12<>0,"Budget mismatch","Match")) -> Match
A13: =Register_A!A13 -> PRJ-011 | B13: =Register_A!B13 -> Workforce Planning Tool | C13: =Register_A!G13 -> 425000 | D13: =LOWER(TRIM(B13)) -> workforce planning tool | E13: =IFERROR(INDEX(Register_B!$A$2:$A$23,MATCH(D13,Register_B!$F$2:$F$23,0)),"NOT FOUND") -> NOT FOUND | F13: =IF(E13="NOT FOUND","",INDEX(Register_B!$C$2:$C$23,MATCH(E13,Register_B!$A$2:$A$23,0))) | G13: =IF(F13="","",F13-C13) | H13: =IF(E13="NOT FOUND","Missing in finance",IF(G13<>0,"Budget mismatch","Match")) -> Missing in finance
... A20: =Register_A!A20 -> PRJ-018 | B20: =Register_A!B20 -> Service Desk Replacement | C20: =Register_A!G20 -> 530000 | D20: =LOWER(TRIM(B20)) -> service desk replacement | E20: =IFERROR(INDEX(Register_B!$A$2:$A$23,MATCH(D20,Register_B!$F$2:$F$23,0)),"NOT FOUND") -> FIN-116 | F20: =IF(E20="NOT FOUND","",INDEX(Register_B!$C$2:$C$23,MATCH(E20,Register_B!$A$2:$A$23,0))) -> 530000 | G20: =IF(F20="","",F20-C20) -> 0 | H20: =IF(E20="NOT FOUND","Missing in finance",IF(G20<>0,"Budget mismatch","Match")) -> Match
A21: =Register_A!A21 -> PRJ-019 | B21: =Register_A!B21 -> GIS Mapping Upgrade | C21: =Register_A!G21 -> 90000 | D21: GIS mapping upgrade | E21: =IFERROR(INDEX(Register_B!$A$2:$A$23,MATCH(D21,Register_B!$F$2:$F$23,0)),"NOT FOUND") -> NOT FOUND | F21: =IF(E21="NOT FOUND","",INDEX(Register_B!$C$2:$C$23,MATCH(E21,Register_B!$A$2:$A$23,0))) | G21: =IF(F21="","",F21-C21) | H21: =IF(E21="NOT FOUND","Missing in finance",IF(G21<>0,"Budget mismatch","Match")) -> Missing in finance
A22: =Register_A!A22 -> PRJ-020 | B22: =Register_A!B22 -> Procurement Portal | C22: =Register_A!G22 -> 560000 | D22: =LOWER(TRIM(B22)) -> procurement portal | E22: =IFERROR(INDEX(Register_B!$A$2:$A$23,MATCH(D22,Register_B!$F$2:$F$23,0)),"NOT FOUND") -> FIN-117 | F22: =IF(E22="NOT FOUND","",INDEX(Register_B!$C$2:$C$23,MATCH(E22,Register_B!$A$2:$A$23,0))) -> 530000 | G22: =IF(F22="","",F22-C22) -> -30000 | H22: =IF(E22="NOT FOUND","Missing in finance",IF(G22<>0,"Budget mismatch","Match")) -> Budget mismatch
A23: =Register_A!A23 -> PRJ-021 | B23: =Register_A!B23 -> Document Management Upgrade | C23: =Register_A!G23 -> 185000 | D23: =LOWER(TRIM(B23)) -> document management upgrade | E23: =IFERROR(INDEX(Register_B!$A$2:$A$23,MATCH(D23,Register_B!$F$2:$F$23,0)),"NOT FOUND") -> FIN-118 | F23: =IF(E23="NOT FOUND","",INDEX(Register_B!$C$2:$C$23,MATCH(E23,Register_B!$A$2:$A$23,0))) -> 185000 | G23: =IF(F23="","",F23-C23) -> 0 | H23: =IF(E23="NOT FOUND","Missing in finance",IF(G23<>0,"Budget mismatch","Match")) -> Match
A24: =Register_A!A24 -> PRJ-022 | B24: =Register_A!B24 -> Data Governance Framework | C24: =Register_A!G24 -> 185000 | D24: =LOWER(TRIM(B24)) -> data governance framework | E24: =IFERROR(INDEX(Register_B!$A$2:$A$23,MATCH(D24,Register_B!$F$2:$F$23,0)),"NOT FOUND") -> FIN-119 | F24: =IF(E24="NOT FOUND","",INDEX(Register_B!$C$2:$C$23,MATCH(E24,Register_B!$A$2:$A$23,0))) -> 185000 | G24: =IF(F24="","",F24-C24) -> 0 | H24: =IF(E24="NOT FOUND","Missing in finance",IF(G24<>0,"Budget mismatch","Match")) -> Match
A25: =Register_A!A25 -> PRJ-023 | B25: =Register_A!B25 -> Electric Vehicle Charging | C25: =Register_A!G25 -> 130000 | D25: =LOWER(TRIM(B25)) -> electric vehicle charging | E25: =IFERROR(INDEX(Register_B!$A$2:$A$23,MATCH(D25,Register_B!$F$2:$F$23,0)),"NOT FOUND") -> NOT FOUND | F25: =IF(E25="NOT FOUND","",INDEX(Register_B!$C$2:$C$23,MATCH(E25,Register_B!$A$2:$A$23,0))) | G25: =IF(F25="","",F25-C25) | H25: =IF(E25="NOT FOUND","Missing in finance",IF(G25<>0,"Budget mismatch","Match")) -> Missing in finance
A26: =Register_A!A26 -> PRJ-024 | B26: =Register_A!B26 -> Council Meeting Livestream | C26: =Register_A!G26 -> 435000 | D26: =LOWER(TRIM(B26)) -> council meeting livestream | E26: =IFERROR(INDEX(Register_B!$A$2:$A$23,MATCH(D26,Register_B!$F$2:$F$23,0)),"NOT FOUND") -> NOT FOUND | F26: =IF(E26="NOT FOUND","",INDEX(Register_B!$C$2:$C$23,MATCH(E26,Register_B!$A$2:$A$23,0))) | G26: =IF(F26="","",F26-C26) | H26: =IF(E26="NOT FOUND","Missing in finance",IF(G26<>0,"Budget mismatch","Match")) -> Missing in finance

Sheet Ex3_Risks
A1: Risk ID | B1: Project ID | C1: Owner | D1: Likelihood | E1: Impact | F1: Next Review | G1: Status | H1: Risk Score (L×I) | I1: Rating | J1: Overdue? | K1: Owner Missing? | L1: Project Exists?
A2: =Risk_Log!A2 -> R-001 | B2: =Risk_Log!B2 -> PRJ-010 | C2: =IF(Risk_Log!D2="","",Risk_Log!D2) -> Daniel Park | D2: =Risk_Log!E2 -> 5 | E2: =Risk_Log!F2 -> 5 | F2: =Risk_Log!G2 -> 46357 | G2: =Risk_Log!H2 -> Monitoring | H2: =D2*E2 -> 25 | I2: =IF(H2>=15,"High",IF(H2>=8,"Medium","Low")) -> High | J2: =IF(AND(G2<>"Closed",F2<TODAY()),"OVERDUE","OK") -> OK | K2: =IF(C2="","MISSING","OK") -> OK | L2: =IF(COUNTIF(Register_A!$A$2:$A$26,B2)=0,"ORPHAN","OK") -> OK
A3: =Risk_Log!A3 -> R-002 | B3: =Risk_Log!B3 -> PRJ-020 | C3: =IF(Risk_Log!D3="","",Risk_Log!D3) -> James Wilson | D3: =Risk_Log!E3 -> 1 | E3: =Risk_Log!F3 -> 4 | F3: =Risk_Log!G3 -> 46379 | G3: =Risk_Log!H3 -> Open | H3: =D3*E3 -> 4 | I3: =IF(H3>=15,"High",IF(H3>=8,"Medium","Low")) -> Low | J3: =IF(AND(G3<>"Closed",F3<TODAY()),"OVERDUE","OK") -> OK | K3: =IF(C3="","MISSING","OK") -> OK | L3: =IF(COUNTIF(Register_A!$A$2:$A$26,B3)=0,"ORPHAN","OK") -> OK
A4: =Risk_Log!A4 -> R-003 | B4: =Risk_Log!B4 -> PRJ-015 | C4: =IF(Risk_Log!D4="","",Risk_Log!D4) -> Sarah Jones | D4: =Risk_Log!E4 -> 3 | E4: =Risk_Log!F4 -> 1 | F4: =Risk_Log!G4 -> 46380 | G4: =Risk_Log!H4 -> Monitoring | H4: =D4*E4 -> 3 | I4: =IF(H4>=15,"High",IF(H4>=8,"Medium","Low")) -> Low | J4: =IF(AND(G4<>"Closed",F4<TODAY()),"OVERDUE","OK") -> OK | K4: =IF(C4="","MISSING","OK") -> OK | L4: =IF(COUNTIF(Register_A!$A$2:$A$26,B4)=0,"ORPHAN","OK") -> OK
A5: =Risk_Log!A5 -> R-004 | B5: =Risk_Log!B5 -> PRJ-014 | C5: =IF(Risk_Log!D5="","",Risk_Log!D5) -> James Wilson | D5: =Risk_Log!E5 -> 2 | E5: =Risk_Log!F5 -> 2 | F5: =Risk_Log!G5 -> 46204 | G5: =Risk_Log!H5 -> Open | H5: =D5*E5 -> 4 | I5: =IF(H5>=15,"High",IF(H5>=8,"Medium","Low")) -> Low | J5: =IF(AND(G5<>"Closed",F5<TODAY()),"OVERDUE","OK") -> OVERDUE | K5: =IF(C5="","MISSING","OK") -> OK | L5: =IF(COUNTIF(Register_A!$A$2:$A$26,B5)=0,"ORPHAN","OK") -> OK
A6: =Risk_Log!A6 -> R-005 | B6: =Risk_Log!B6 -> PRJ-018 | C6: =IF(Risk_Log!D6="","",Risk_Log!D6) -> Mei Chen | D6: =Risk_Log!E6 -> 5 | E6: =Risk_Log!F6 -> 5 | F6: =Risk_Log!G6 -> 46287 | G6: =Risk_Log!H6 -> Open | H6: =D6*E6 -> 25 | I6: =IF(H6>=15,"High",IF(H6>=8,"Medium","Low")) -> High | J6: =IF(AND(G6<>"Closed",F6<TODAY()),"OVERDUE","OK") -> OVERDUE | K6: =IF(C6="","MISSING","OK") -> OK | L6: =IF(COUNTIF(Register_A!$A$2:$A$26,B6)=0,"ORPHAN","OK") -> OK
A7: =Risk_Log!A7 -> R-006 | B7: =Risk_Log!B7 -> PRJ-031 | C7: =IF(Risk_Log!D7="","",Risk_Log!D7) | D7: =Risk_Log!E7 -> 2 | E7: =Risk_Log!F7 -> 1 | F7: =Risk_Log!G7 -> 46199 | G7: =Risk_Log!H7 -> Open | H7: =D7*E7 -> 2 | I7: =IF(H7>=15,"High",IF(H7>=8,"Medium","Low")) -> Low | J7: =IF(AND(G7<>"Closed",F7<TODAY()),"OVERDUE","OK") -> OVERDUE | K7: =IF(C7="","MISSING","OK") -> MISSING | L7: =IF(COUNTIF(Register_A!$A$2:$A$26,B7)=0,"ORPHAN","OK") -> ORPHAN
A8: =Risk_Log!A8 -> R-007 | B8: =Risk_Log!B8 -> PRJ-016 | C8: =IF(Risk_Log!D8="","",Risk_Log!D8) -> Sarah Jones | D8: =Risk_Log!E8 -> 2 | E8: =Risk_Log!F8 -> 2 | F8: =Risk_Log!G8 -> 46182 | G8: =Risk_Log!H8 -> Open | H8: =D8*E8 -> 4 | I8: =IF(H8>=15,"High",IF(H8>=8,"Medium","Low")) -> Low | J8: =IF(AND(G8<>"Closed",F8<TODAY()),"OVERDUE","OK") -> OVERDUE | K8: =IF(C8="","MISSING","OK") -> OK | L8: =IF(COUNTIF(Register_A!$A$2:$A$26,B8)=0,"ORPHAN","OK") -> OK
A9: =Risk_Log!A9 -> R-008 | B9: =Risk_Log!B9 -> PRJ-009 | C9: =IF(Risk_Log!D9="","",Risk_Log!D9) -> Liam O'Brien | D9: =Risk_Log!E9 -> 5 | E9: =Risk_Log!F9 -> 3 | F9: =Risk_Log!G9 -> 46252 | G9: =Risk_Log!H9 -> Monitoring | H9: =D9*E9 -> 15 | I9: =IF(H9>=15,"High",IF(H9>=8,"Medium","Low")) -> High | J9: =IF(AND(G9<>"Closed",F9<TODAY()),"OVERDUE","OK") -> OVERDUE | K9: =IF(C9="","MISSING","OK") -> OK | L9: =IF(COUNTIF(Register_A!$A$2:$A$26,B9)=0,"ORPHAN","OK") -> OK
A10: =Risk_Log!A10 -> R-009 | B10: =Risk_Log!B10 -> PRJ-005 | C10: =IF(Risk_Log!D10="","",Risk_Log!D10) -> Tom Nguyen | D10: =Risk_Log!E10 -> 4 | E10: =Risk_Log!F10 -> 5 | F10: =Risk_Log!G10 -> 46373 | G10: =Risk_Log!H10 -> Monitoring | H10: =D10*E10 -> 20 | I10: =IF(H10>=15,"High",IF(H10>=8,"Medium","Low")) -> High | J10: =IF(AND(G10<>"Closed",F10<TODAY()),"OVERDUE","OK") -> OK | K10: =IF(C10="","MISSING","OK") -> OK | L10: =IF(COUNTIF(Register_A!$A$2:$A$26,B10)=0,"ORPHAN","OK") -> OK
A11: =Risk_Log!A11 -> R-010 | B11: =Risk_Log!B11 -> PRJ-016 | C11: =IF(Risk_Log!D11="","",Risk_Log!D11) | D11: =Risk_Log!E11 -> 2 | E11: =Risk_Log!F11 -> 5 | F11: =Risk_Log!G11 -> 46296 | G11: =Risk_Log!H11 -> Monitoring | H11: =D11*E11 -> 10 | I11: =IF(H11>=15,"High",IF(H11>=8,"Medium","Low")) -> Medium | J11: =IF(AND(G11<>"Closed",F11<TODAY()),"OVERDUE","OK") -> OVERDUE | K11: =IF(C11="","MISSING","OK") -> MISSING | L11: =IF(COUNTIF(Register_A!$A$2:$A$26,B11)=0,"ORPHAN","OK") -> OK
A12: =Risk_Log!A12 -> R-011 | B12: =Risk_Log!B12 -> PRJ-024 | C12: =IF(Risk_Log!D12="","",Risk_Log!D12) -> Priya Sharma | D12: =Risk_Log!E12 -> 2 | E12: =Risk_Log!F12 -> 2 | F12: =Risk_Log!G12 -> 46219 | G12: =Risk_Log!H12 -> Closed | H12: =D12*E12 -> 4 | I12: =IF(H12>=15,"High",IF(H12>=8,"Medium","Low")) -> Low | J12: =IF(AND(G12<>"Closed",F12<TODAY()),"OVERDUE","OK") -> OK | K12: =IF(C12="","MISSING","OK") -> OK | L12: =IF(COUNTIF(Register_A!$A$2:$A$26,B12)=0,"ORPHAN","OK") -> OK
A13: =Risk_Log!A13 -> R-012 | B13: =Risk_Log!B13 -> PRJ-023 | C13: =IF(Risk_Log!D13="","",Risk_Log!D13) | D13: =Risk_Log!E13 -> 1 | E13: =Risk_Log!F13 -> 3 | F13: =Risk_Log!G13 -> 46343 | G13: =Risk_Log!H13 -> Closed | H13: =D13*E13 -> 3 | I13: =IF(H13>=15,"High",IF(H13>=8,"Medium","Low")) -> Low | J13: =IF(AND(G13<>"Closed",F13<TODAY()),"OVERDUE","OK") -> OK | K13: =IF(C13="","MISSING","OK") -> MISSING | L13: =IF(COUNTIF(Register_A!$A$2:$A$26,B13)=0,"ORPHAN","OK") -> OK
... A41: =Risk_Log!A41 -> R-040 | B41: =Risk_Log!B41 -> PRJ-002 | C41: =IF(Risk_Log!D41="","",Risk_Log!D41) -> Liam O'Brien | D41: =Risk_Log!E41 -> 3 | E41: =Risk_Log!F41 -> 2 | F41: =Risk_Log!G41 -> 46184 | G41: =Risk_Log!H41 -> Monitoring | H41: =D41*E41 -> 6 | I41: =IF(H41>=15,"High",IF(H41>=8,"Medium","Low")) -> Low | J41: =IF(AND(G41<>"Closed",F41<TODAY()),"OVERDUE","OK") -> OVERDUE | K41: =IF(C41="","MISSING","OK") -> OK | L41: =IF(COUNTIF(Register_A!$A$2:$A$26,B41)=0,"ORPHAN","OK") -> OK

Sheet Ex4_Summary
A1: Question | B1: Answer | C1: Formula hint
A2: How many projects are in Register_A (incl. duplicate)? | B2: =COUNTA(Register_A!A2:A26) -> 25 | C2: COUNTA counts non-empty cells
A3: How many projects are Red? | B3: =COUNTIF(Register_A!H2:H26,"Red") -> 5 | C3: COUNTIF(range,"Red")
A4: Total budget of the Digital division ($) | B4: =SUMIFS(Register_A!G2:G26,Register_A!D2:D26,"Digital") -> 2600000 | C4: SUMIFS(sum_range, criteria_range, criteria)
A5: How many Digital projects are Amber? | B5: =COUNTIFS(Register_A!D2:D26,"Digital",Register_A!H2:H26,"Amber*") -> 1 | C5: COUNTIFS with 2 conditions (watch the messy 'amber ' → use "Amber*")
A6: Average budget per project ($) | B6: =AVERAGE(Register_A!G2:G26) -> 335200 | C6: AVERAGE
A7: How many risks are still Open? | B7: =COUNTIF(Risk_Log!H2:H41,"Open") -> 26 | C7: COUNTIF
A8: How many open risks are High (score ≥ 15)? | B8: =COUNTIFS(Ex3_Risks!H2:H41,">=15",Ex3_Risks!G2:G41,"<>Closed") -> 7 | C8: Needs Ex3_Risks finished first
A9: How many projects are missing from the finance register? | B9: =COUNTIF(Ex2_Crosswalk!H2:H26,"Missing in finance") -> 6 | C9: Needs Ex2_Crosswalk finished first
A10: Total Actual to Date spent across Register_B ($) | B10: =SUM(Register_B!E2:E23) -> 4474000 | C10: SUM

Sheet Answers
A1: ANSWERS: formulas for the first rows of each exercise. Copy them down in your sheet the same way.
A3: Ex1_Clean
A4: Column | B4: Formula (row 3 shown) | C4: What it does
A5: Clean Name =TRIM(PROPER()) | B5: '=TRIM(PROPER(B3)) | C5: PROPER fixes capitals, TRIM removes extra spaces
A6: Clean Status | B6: '=TRIM(PROPER(D3)) | C6: Same cleaning so 'amber ' becomes 'Amber'
A7: Owner Missing? | B7: '=IF(C3="","MISSING","OK") | C7: IF the cell is empty → MISSING
A8: Duplicate ID? | B8: '=IF(COUNTIF($A$2:$A$26,A3)>1,"DUPLICATE","OK") | C8: COUNTIF counts how many times this ID appears; >1 = duplicate
A9: Dates OK? | B9: '=IF(Register_A!F3<Register_A!E3,"END BEFORE START","OK") | C9: End date earlier than start date is impossible
A11: Ex2_Crosswalk
A12: Column | B12: Formula (row 3 shown) | C12: What it does
A13: Match Key (clean name) | B13: '=LOWER(TRIM(B3)) | C13: Lower-case + trimmed so 'CUSTOMER portal ' matches 'Customer Portal'
A14: Finance Code | B14: '=IFERROR(INDEX(Register_B!$A$2:$A$23,MATCH(D3,Register_B!$F$2:$F$23,0)),"NOT FOUND") | C14: MATCH finds the row of the same clean name in Register_B (column F helper), INDEX returns the code from that row. XLOOKUP version: =XLOOKUP(D3, Register_B!$F$2:$F$23, Register_B!$A$2:$A$23, "NOT FOUND")
A15: Budget B ($) | B15: '=IF(E3="NOT FOUND","",INDEX(Register_B!$C$2:$C$23,MATCH(E3,Register_B!$A$2:$A$23,0))) | C15: Looks up the approved budget using the finance code
A16: Difference ($) | B16: '=IF(F3="","",F3-C3) | C16: Finance budget minus PMO budget; not 0 = conflict to log
A17: Result | B17: '=IF(E3="NOT FOUND","Missing in finance",IF(G3<>0,"Budget mismatch","Match")) | C17: Nested IF gives a plain-English status
A19: Ex3_Risks
A20: Column | B20: Formula (row 3 shown) | C20: What it does
A21: Risk Score (L×I) | B21: '=D3*E3 | C21: Standard risk matrix: likelihood × impact
A22: Rating | B22: '=IF(H3>=15,"High",IF(H3>=8,"Medium","Low")) | C22: Nested IF bands: ≥15 High, ≥8 Medium, else Low
A23: Overdue? | B23: '=IF(AND(G3<>"Closed",F3<TODAY()),"OVERDUE","OK") | C23: AND: still open AND review date already passed
A24: Owner Missing? | B24: '=IF(C3="","MISSING","OK") | C24: IF the cell is empty → MISSING
A25: Project Exists? | B25: '=IF(COUNTIF(Register_A!$A$2:$A$26,B3)=0,"ORPHAN","OK") | C25: COUNTIF=0 means this risk points to a project that isn't in the register
A28: Expected findings to check yourself against:
A29: • Register_A: PRJ-009 appears twice (duplicate row).
A30: • Register_A: PRJ-007 has no owner.
A31: • Register_A: PRJ-012 ends before it starts (date error).
A32: • Register_A: PRJ-015 name has extra spaces and lower case; PRJ-004 status is 'amber ' (messy).
A33: • Watch out: PROPER turns 'GIS' into 'Gis' (PRJ-019). Cleaning functions can create new errors, so always eyeball results.
A34: • Crosswalk: 16 projects match exactly; 3 have budget conflicts (PRJ-002, PRJ-016, PRJ-020).
A35: • Crosswalk: 6 show NOT FOUND. Four are truly missing from finance (PRJ-008, 011, 019, 023).
A36: • …but two are the SAME project under a different name: PRJ-013 = FIN-111 'IAM Program', PRJ-024 = FIN-120 'Council Livestreaming'. Formulas can't catch this; you record it manually in the crosswalk and issue log.
A37: • Register_B has 2 projects not in the PMO register at all: FIN-121 Library Self-Checkout Kiosks, FIN-122 Parking Sensor Trial. Log them for management; don't delete them.
A38: • Risk_Log: R-006 (PRJ-031) and R-023 (PRJ-045) point to projects that don't exist (orphans).
A39: • Risk_Log: 9 risks have no owner. Risk ratings: 9 High, 10 Medium, 21 Low.
A40: • Overdue count depends on today's date, so yours will differ over time. That's what TODAY() does.

Sheet Issue_Log
A1: Issue ID | B1: Sheet | C1: Record | D1: Problem | E1: Impact | F1: Suggested Action | G1: Status
A2: ISS-001 | B2: Register_A | C2: PRJ-009 | D2: Duplicate row | E2: Corporate budget overstated by $270,000; totals show 25 projects instead of 24 | F2: PMO to confirm and remove the duplicate | G2: Open
A3: ISS-002 | B3: Register_A | C3: PRJ-007 | D3: No owner assigned | E3: Nobody is accountable for this $160,000 project, so delays, risks and budget issues may go unmanaged | F3: PMO to confirm the owner with the Digital division manager and update the register | G3: Open
A4: ISS-003 | B4: Register_A | C4: PRJ-012 | D4: End date is before start date | E4: Project duration can't be calculated, so schedule and overdue reports for this project are wrong | F4: PMO to confirm correct dates with the project owner and update the register | G4: Open
A5: ISS-004 | B5: Register_A | C5: PRJ-004 | D5: Status entered as "amber " (lowercase, trailing space) | E5: Pivots and charts split Amber into two groups, so the Amber count is understated by 1 | F5: PMO to correct the value; add a Status dropdown to prevent recurrence | G5: Open
A6: ISS-005 | B6: Register_A | C6: PRJ-015 | D6: Name has extra spaces and lowercase | E6: Lookups against other registers can fail, so the project may wrongly show as missing | F6: PMO to correct the name; apply TRIM/PROPER cleaning before matching | G6: Open
A7: ISS-006 | B7: Register_A / Register_B | C7: PRJ-002, PRJ-016, PRJ-020 | D7: Budget differs between PMO and Finance | E7: Finance approved $75,000 less in total (PRJ-002 -$15,000; PRJ-016 -$30,000; PRJ-020 -$30,000); unclear which figure is correct | F7: Finance and PMO to agree the approved budget and document the source for each | G7: Open
A8: ISS-007 | B8: Register_B | C8: PRJ-013 / FIN-111; PRJ-024 / FIN-120 | D8: Same project recorded under different names ("IAM Program", "Council Livestreaming") | E8: Automated matching reports them as missing, overstating gaps between the registers | F8: Linked manually in crosswalk; Finance to adopt PMO project names or record the PMO Project ID | G8: Open
A9: ISS-008 | B9: Register_A | C9: PRJ-008, PRJ-011, PRJ-019, PRJ-023 | D9: Active projects have no Finance record | E9: Spend on 4 projects may be untracked or unapproved | F9: Finance to confirm whether budgets were approved and add records | G9: Open
A10: ISS-009 | B10: Register_B | C10: FIN-121, FIN-122 | D10: Finance projects not in PMO register (Library Self-Checkout Kiosks, Parking Sensor Trial) | E10: $155,000 of approved budget has no PMO oversight | F10: PMO to confirm whether these are projects and add them to the register | G10: Open
A11: ISS-010 | B11: Risk_Log | C11: R-006, R-023 | D11: Risks linked to non-existent projects (PRJ-031, PRJ-045) | E11: These risks can't be reported against any project and may be overlooked | F11: Risk owners to confirm the correct Project ID | G11: Open
A12: ISS-011 | B12: Risk_Log | C12: R-006, R-010, R-012, R-014, R-015, R-016, R-021, R-026, R-032 | D12: 9 risks have no owner | E12: Nobody is responsible for monitoring or mitigating these risks | F12: PMO to assign owners at the next risk review | G12: Open
A13: ISS-012 | B13: Process | C13: All registers | D13: No shared Project ID between PMO and Finance | E13: Every reconciliation depends on name matching, which is slow and error-prone | F13: Add PMO Project ID as a mandatory field in the Finance register | G13: Open
A26: Summary Sheet
A27: 1. Reviewed 25 PMO register rows (24 unique projects), 22 Finance records and 40 risks.
A28: 2. 16 projects match exactly between PMO and Finance; 2 more were matched manually because they are recorded under different names.
A29: 3. 3 projects have budget conflicts totalling $75,000, and 4 active projects have no Finance record.
A30: 4. Data quality issues include a duplicate row, a missing owner, an invalid date, inconsistent status values, 9 unowned risks and 2 risks linked to non-existent projects.
A31: 5. Decisions needed: agree the correct budgets for 3 projects, confirm funding for 4 unrecorded projects, and require a shared Project ID in both registers.

Sheet finance_Clean
A1: Finance Code | B1: Project Title | C1: PMO Ref | D1: Approved Budget | E1: Forecast | F1: Actual to Date | G1: Last Updated
A2: FIN-103 | B2: Records Digitisation | C2: PRJ-003 | D2: 190000 | E2: 169000 | F2: 105000 | G2: 15/9/2026
A3: FIN-115 | B3: Contract Management Platform | C3: PRJ-017 | D3: 335000 | E3: 399000 | F3: 321000 | G3: 28/9/2026
A4: FIN-114 | B4: Cloud Email Migration | C4: PRJ-016 | D4: 535000 | E4: 626000 | F4: 457000 | G4: 18/9/2026
A5: FIN-113 | B5: Website Accessibility Fixes | C5: PRJ-015 | D5: 465000 | E5: 429000 | F5: 372000 | G5: 28/9/2026
A6: FIN-107 | B6: Mobile Inspections App | C6: PRJ-007 | D6: 160000 | E6: 172000 | F6: 149000 | G6: 25/9/2026
A7: FIN-102 | B7: Payroll System Replacement | C7: PRJ-002 | D7: 360000 | E7: 301000 | F7: 104000 | G7: 15/9/2026
A8: FIN-118 | B8: Document Management Upgrade | C8: PRJ-021 | D8: 185000 | E8: 197000 | F8: 148000 | G8: 15/9/2026
A9: FIN-122 | B9: Parking Sensor Trial | D9: 60000 | E9: 52000 | F9: 30000 | G9: 17/9/2026
A10: FIN-111 | B10: Iam Program | C10: PRJ-013 | D10: 395000 | E10: 439000 | F10: 315000 | G10: 28/9/2026
A11: FIN-108 | B11: Grants Management System | C11: PRJ-009 | D11: 270000 | E11: 264000 | F11: 76000 | G11: 19/9/2026
A12: FIN-106 | B12: Data Warehouse Migration | C12: PRJ-006 | D12: 405000 | E12: 468000 | F12: 295000 | G12: 7/9/2026
A13: FIN-110 | B13: Call Centre Modernisation | C13: PRJ-012 | D13: 135000 | E13: 129000 | F13: 39000 | G13: 6/9/2026
A14: FIN-120 | B14: Council Livestreaming | C14: PRJ-024 | D14: 435000 | E14: 482000 | F14: 173000 | G14: 26/9/2026
A15: FIN-104 | B15: Cyber Security Uplift | C15: PRJ-004 | D15: 440000 | E15: 374000 | F15: 114000 | G15: 17/9/2026
A16: FIN-105 | B16: Fleet Telematics Rollout | C16: PRJ-005 | D16: 585000 | E16: 692000 | F16: 436000 | G16: 16/9/2026
A17: FIN-121 | B17: Library Self-Checkout Kiosks | D17: 95000 | E17: 98000 | F17: 41000 | G17: 21/9/2026
A18: FIN-109 | B18: Asset Register Cleanup | C18: PRJ-010 | D18: 90000 | E18: 108000 | F18: 57000 | G18: 20/9/2026
A19: FIN-119 | B19: Data Governance Framework | C19: PRJ-022 | D19: 185000 | E19: 209000 | F19: 162000 | G19: 26/9/2026
A20: FIN-101 | B20: Customer Portal Upgrade | C20: PRJ-001 | D20: 455000 | E20: 450000 | F20: 123000 | G20: 6/9/2026
A21: FIN-112 | B21: Budget Reporting Automation | C21: PRJ-014 | D21: 550000 | E21: 627000 | F21: 196000 | G21: 4/9/2026
A22: FIN-116 | B22: Service Desk Replacement | C22: PRJ-018 | D22: 530000 | E22: 547000 | F22: 457000 | G22: 15/9/2026
A23: FIN-117 | B23: Procurement Portal | C23: PRJ-020 | D23: 530000 | E23: 551000 | F23: 304000 | G23: 10/9/2026

Sheet PMO_Clean
A1: Project ID | B1: Initiative Name | C1: Owner Name | D1: Division | E1: Start Date | F1: End Date | G1: Budget | H1: Status | I1: Budget Band
A2: PRJ-001 | B2: Customer Portal Upgrade | C2: Priya Sharma | D2: Digital | E2: 05/06/2025 | F2: 23/04/2026 | G2: 455000 | H2: Green | I2: Large
A3: PRJ-002 | B3: Payroll System Replacement | C3: Liam O'Brien | D3: Digital | E3: 19/06/2025 | F3: 15/11/2025 | G3: 360000 | H3: Green | I3: Medium
A4: PRJ-003 | B4: Records Digitisation | C4: James Wilson | D4: Community | E4: 14/07/2025 | F4: 16/12/2025 | G4: 190000 | H4: Green | I4: Small
A5: PRJ-004 | B5: Cyber Security Uplift | C5: Priya Sharma | D5: Community | E5: 04/10/2025 | F5: 26/05/2026 | G5: 440000 | H5: Amber | I5: Large
A6: PRJ-005 | B6: Fleet Telematics Rollout | C6: Mei Chen | D6: Operations | E6: 02/04/2025 | F6: 12/05/2026 | G6: 585000 | H6: Complete | I6: Large
A7: PRJ-006 | B7: Data Warehouse Migration | C7: Aisha Khan | D7: Corporate | E7: 18/03/2025 | F7: 14/09/2025 | G7: 405000 | H7: Green | I7: Large
A8: PRJ-007 | B8: Mobile Inspections App | D8: Digital | E8: 19/10/2025 | F8: 09/01/2027 | G8: 160000 | H8: Green | I8: Small
A9: PRJ-008 | B9: Office Network Refresh | C9: Daniel Park | D9: Community | E9: 02/10/2025 | F9: 12/12/2026 | G9: 170000 | H9: Red | I9: Small
A10: PRJ-009 | B10: Grants Management System | C10: Aisha Khan | D10: Corporate | E10: 19/08/2025 | F10: 06/08/2026 | G10: 270000 | H10: Amber | I10: Medium
A11: PRJ-010 | B11: Asset Register Cleanup | C11: Aisha Khan | D11: Community | E11: 25/12/2025 | F11: 26/08/2026 | G11: 90000 | H11: Red | I11: Small
A12: PRJ-011 | B12: Workforce Planning Tool | C12: James Wilson | D12: Digital | E12: 15/12/2025 | F12: 08/09/2026 | G12: 425000 | H12: Complete | I12: Large
A13: PRJ-012 | B13: Call Centre Modernisation | C13: Daniel Park | D13: Community | E13: 25/03/2025 | F13: 23/02/2025 | G13: 135000 | H13: Green | I13: Small
A14: PRJ-013 | B14: Identity & Access Management | C14: Tom Nguyen | D14: Operations | E14: 03/11/2025 | F14: 29/03/2027 | G14: 395000 | H14: Red | I14: Medium
A15: PRJ-014 | B15: Budget Reporting Automation | C15: Daniel Park | D15: Digital | E15: 16/10/2025 | F15: 06/12/2026 | G15: 550000 | H15: Green | I15: Large
A16: PRJ-015 | B16: Website Accessibility Fixes | C16: James Wilson | D16: Digital | E16: 16/05/2025 | F16: 04/09/2026 | G16: 465000 | H16: Red | I16: Large
A17: PRJ-016 | B17: Cloud Email Migration | C17: Daniel Park | D17: Operations | E17: 19/11/2025 | F17: 02/03/2027 | G17: 565000 | H17: Complete | I17: Large
A18: PRJ-017 | B18: Contract Management Platform | C18: Tom Nguyen | D18: Corporate | E18: 12/11/2025 | F18: 23/03/2026 | G18: 335000 | H18: Green | I18: Medium
A19: PRJ-018 | B19: Service Desk Replacement | C19: Aisha Khan | D19: Corporate | E19: 02/08/2025 | F19: 21/03/2026 | G19: 530000 | H19: Amber | I19: Large
A20: PRJ-019 | B20: GIS Mapping Upgrade | C20: Mei Chen | D20: Community | E20: 13/07/2025 | F20: 22/07/2026 | G20: 90000 | H20: Complete | I20: Small
... A25: PRJ-024 | B25: Council Meeting Livestream | C25: Priya Sharma | D25: Community | E25: 23/03/2025 | F25: 10/04/2026 | G25: 435000 | H25: Complete | I25: Large

Sheet Spend_Q1
A1: Month | B1: Finance Code | C1: Category | D1: Amount
A2: 46204 | B2: FIN-107 | C2: Licences | D2: 1500
A3: 46204 | B3: FIN-114 | C3: Vendor | D3: 19500
A4: 46204 | B4: FIN-114 | C4: Licences | D4: 7000
A5: 46204 | B5: FIN-119 | C5: Licences | D5: 10000
A6: 46204 | B6: FIN-115 | C6: Labour | D6: 15500
A7: 46204 | B7: FIN-115 | C7: Licences | D7: 9500
A8: 46204 | B8: FIN-120 | C8: Licences | D8: 9000
A9: 46204 | B9: FIN-120 | C9: Labour | D9: 11000
A10: 46204 | B10: FIN-105 | C10: Licences | D10: 10000
A11: 46204 | B11: FIN-102 | C11: Labour | D11: 19000
A12: 46204 | B12: FIN-108 | C12: Vendor | D12: 4000
A13: 46204 | B13: FIN-103 | C13: Vendor | D13: 1500
... A61: 46266 | B61: FIN-106 | C61: Labour | D61: 11500

Sheet Missing_in_Finance
A1: Project ID | B1: Initiative Name | C1: Owner Name | D1: Division | E1: Start Date | F1: End Date | G1: Budget | H1: Status | I1: Budget Band
A2: PRJ-008 | B2: Office Network Refresh | C2: Daniel Park | D2: Community | E2: 02/10/2025 | F2: 12/12/2026 | G2: 170000 | H2: Red | I2: Small
A3: PRJ-011 | B3: Workforce Planning Tool | C3: James Wilson | D3: Digital | E3: 15/12/2025 | F3: 08/09/2026 | G3: 425000 | H3: Complete | I3: Large
A4: PRJ-019 | B4: GIS Mapping Upgrade | C4: Mei Chen | D4: Community | E4: 13/07/2025 | F4: 22/07/2026 | G4: 90000 | H4: Complete | I4: Small
A5: PRJ-023 | B5: Electric Vehicle Charging | C5: Sarah Jones | D5: Operations | E5: 10/05/2025 | F5: 09/09/2025 | G5: 130000 | H5: Red | I5: Small

Sheet Crosswalk
A1: Project ID | B1: Initiative Name | C1: Owner Name | D1: Division | E1: Start Date | F1: End Date | G1: Budget | H1: Status | I1: Budget Band | J1: Finance Code | K1: Approved Budget | L1: Budget Difference
A2: PRJ-001 | B2: Customer Portal Upgrade | C2: Priya Sharma | D2: Digital | E2: 05/06/2025 | F2: 23/04/2026 | G2: 455000 | H2: Green | I2: Large | J2: FIN-101 | K2: 455000 | L2: 0
A3: PRJ-003 | B3: Records Digitisation | C3: James Wilson | D3: Community | E3: 14/07/2025 | F3: 16/12/2025 | G3: 190000 | H3: Green | I3: Small | J3: FIN-103 | K3: 190000 | L3: 0
A4: PRJ-002 | B4: Payroll System Replacement | C4: Liam O'Brien | D4: Digital | E4: 19/06/2025 | F4: 15/11/2025 | G4: 360000 | H4: Green | I4: Medium | J4: FIN-102 | K4: 360000 | L4: 0
A5: PRJ-017 | B5: Contract Management Platform | C5: Tom Nguyen | D5: Corporate | E5: 12/11/2025 | F5: 23/03/2026 | G5: 335000 | H5: Green | I5: Medium | J5: FIN-115 | K5: 335000 | L5: 0
A6: PRJ-016 | B6: Cloud Email Migration | C6: Daniel Park | D6: Operations | E6: 19/11/2025 | F6: 02/03/2027 | G6: 565000 | H6: Complete | I6: Large | J6: FIN-114 | K6: 535000 | L6: -30000
A7: PRJ-004 | B7: Cyber Security Uplift | C7: Priya Sharma | D7: Community | E7: 04/10/2025 | F7: 26/05/2026 | G7: 440000 | H7: Amber | I7: Large | J7: FIN-104 | K7: 440000 | L7: 0
A8: PRJ-015 | B8: Website Accessibility Fixes | C8: James Wilson | D8: Digital | E8: 16/05/2025 | F8: 04/09/2026 | G8: 465000 | H8: Red | I8: Large | J8: FIN-113 | K8: 465000 | L8: 0
A9: PRJ-005 | B9: Fleet Telematics Rollout | C9: Mei Chen | D9: Operations | E9: 02/04/2025 | F9: 12/05/2026 | G9: 585000 | H9: Complete | I9: Large | J9: FIN-105 | K9: 585000 | L9: 0
A10: PRJ-007 | B10: Mobile Inspections App | D10: Digital | E10: 19/10/2025 | F10: 09/01/2027 | G10: 160000 | H10: Green | I10: Small | J10: FIN-107 | K10: 160000 | L10: 0
A11: PRJ-006 | B11: Data Warehouse Migration | C11: Aisha Khan | D11: Corporate | E11: 18/03/2025 | F11: 14/09/2025 | G11: 405000 | H11: Green | I11: Large | J11: FIN-106 | K11: 405000 | L11: 0
A12: PRJ-021 | B12: Document Management Upgrade | C12: Mei Chen | D12: Digital | E12: 22/06/2025 | F12: 02/05/2026 | G12: 185000 | H12: Amber | I12: Small | J12: FIN-118 | K12: 185000 | L12: 0
A13: PRJ-008 | B13: Office Network Refresh | C13: Daniel Park | D13: Community | E13: 02/10/2025 | F13: 12/12/2026 | G13: 170000 | H13: Red | I13: Small
A14: PRJ-009 | B14: Grants Management System | C14: Aisha Khan | D14: Corporate | E14: 19/08/2025 | F14: 06/08/2026 | G14: 270000 | H14: Amber | I14: Medium | J14: FIN-108 | K14: 270000 | L14: 0
A15: PRJ-013 | B15: Identity & Access Management | C15: Tom Nguyen | D15: Operations | E15: 03/11/2025 | F15: 29/03/2027 | G15: 395000 | H15: Red | I15: Medium | J15: FIN-111 | K15: 395000 | L15: 0
A16: PRJ-010 | B16: Asset Register Cleanup | C16: Aisha Khan | D16: Community | E16: 25/12/2025 | F16: 26/08/2026 | G16: 90000 | H16: Red | I16: Small | J16: FIN-109 | K16: 90000 | L16: 0
A17: PRJ-011 | B17: Workforce Planning Tool | C17: James Wilson | D17: Digital | E17: 15/12/2025 | F17: 08/09/2026 | G17: 425000 | H17: Complete | I17: Large
A18: PRJ-012 | B18: Call Centre Modernisation | C18: Daniel Park | D18: Community | E18: 25/03/2025 | F18: 23/02/2025 | G18: 135000 | H18: Green | I18: Small | J18: FIN-110 | K18: 135000 | L18: 0
A19: PRJ-014 | B19: Budget Reporting Automation | C19: Daniel Park | D19: Digital | E19: 16/10/2025 | F19: 06/12/2026 | G19: 550000 | H19: Green | I19: Large | J19: FIN-112 | K19: 550000 | L19: 0
A20: PRJ-018 | B20: Service Desk Replacement | C20: Aisha Khan | D20: Corporate | E20: 02/08/2025 | F20: 21/03/2026 | G20: 530000 | H20: Amber | I20: Large | J20: FIN-116 | K20: 530000 | L20: 0
A21: PRJ-022 | B21: Data Governance Framework | C21: Priya Sharma | D21: Community | E21: 08/03/2025 | F21: 08/06/2026 | G21: 185000 | H21: Amber | I21: Small | J21: FIN-119 | K21: 185000 | L21: 0
A22: PRJ-019 | B22: GIS Mapping Upgrade | C22: Mei Chen | D22: Community | E22: 13/07/2025 | F22: 22/07/2026 | G22: 90000 | H22: Complete | I22: Small
A23: PRJ-020 | B23: Procurement Portal | C23: Sarah Jones | D23: Operations | E23: 09/09/2025 | F23: 18/03/2026 | G23: 560000 | H23: Complete | I23: Large | J23: FIN-117 | K23: 530000 | L23: -30000
A24: PRJ-023 | B24: Electric Vehicle Charging | C24: Sarah Jones | D24: Operations | E24: 10/05/2025 | F24: 09/09/2025 | G24: 130000 | H24: Red | I24: Small
A25: PRJ-024 | B25: Council Meeting Livestream | C25: Priya Sharma | D25: Community | E25: 23/03/2025 | F25: 10/04/2026 | G25: 435000 | H25: Complete | I25: Large | J25: FIN-120 | K25: 435000 | L25: 0

Sheet Spend_by_Code
A1: Finance Code | B1: Q1 Spend
A2: FIN-115 | B2: 59000
A3: FIN-106 | B3: 47500
A4: FIN-113 | B4: 45500
A5: FIN-114 | B5: 42000
A6: FIN-120 | B6: 35000
A7: FIN-102 | B7: 30500
A8: FIN-112 | B8: 27000
A9: FIN-103 | B9: 24500
A10: FIN-117 | B10: 23000
A11: FIN-109 | B11: 23000
A12: FIN-118 | B12: 22500
A13: FIN-110 | B13: 19500
... A22: FIN-108 | B22: 4000

Sheet Spend_by_Category
A1: Category | B1: Q1 Spend
A2: Licences | B2: 184000
A3: Labour | B3: 177500
A4: Vendor | B4: 155500

Sheet forecast_by_quarter
A1: Finance Code | B1: Quarter | C1: Forecast
A2: FIN-103 | B2: Q1 FY27 | C2: 51000
A3: FIN-103 | B3: Q2 FY27 | C3: 51000
A4: FIN-103 | B4: Q3 FY27 | C4: 42000
A5: FIN-103 | B5: Q4 FY27 | C5: 25000
A6: FIN-115 | B6: Q1 FY27 | C6: 120000
A7: FIN-115 | B7: Q2 FY27 | C7: 120000
A8: FIN-115 | B8: Q3 FY27 | C8: 100000
A9: FIN-115 | B9: Q4 FY27 | C9: 60000
A10: FIN-114 | B10: Q1 FY27 | C10: 188000
A11: FIN-114 | B11: Q2 FY27 | C11: 188000
A12: FIN-114 | B12: Q3 FY27 | C12: 156000
A13: FIN-114 | B13: Q4 FY27 | C13: 94000
... A89: FIN-117 | B89: Q4 FY27 | C89: 83000

Sheet Missing_in_PMO
A1: Finance Code | B1: Project Title | C1: Approved Budget
A2: FIN-122 | B2: Parking Sensor Trial | C2: 60000
A3: FIN-121 | B3: Library Self-Checkout Kiosks | C3: 95000

Sheet Budget_Burn
A1: Project ID | B1: Initiative Name | C1: Owner Name | D1: Division | E1: Start Date | F1: End Date | G1: Budget | H1: Status | I1: Budget Band | J1: Finance Code | K1: Approved Budget | L1: Budget Difference | M1: Q1 Spend | N1: Burn %
A2: PRJ-010 | B2: Asset Register Cleanup | C2: Aisha Khan | D2: Community | E2: 25/12/2025 | F2: 26/08/2026 | G2: 90000 | H2: Red | I2: Small | J2: FIN-109 | K2: 90000 | L2: 0 | M2: 23000 | N2: 0.25555556
A3: PRJ-017 | B3: Contract Management Platform | C3: Tom Nguyen | D3: Corporate | E3: 12/11/2025 | F3: 23/03/2026 | G3: 335000 | H3: Green | I3: Medium | J3: FIN-115 | K3: 335000 | L3: 0 | M3: 59000 | N3: 0.1761194
A4: PRJ-012 | B4: Call Centre Modernisation | C4: Daniel Park | D4: Community | E4: 25/03/2025 | F4: 23/02/2025 | G4: 135000 | H4: Green | I4: Small | J4: FIN-110 | K4: 135000 | L4: 0 | M4: 19500 | N4: 0.14444444
